Workbook

Sheet WACC
B1: WACC Calculation | G1: Equity | H1: =1140000000*DCF!B6 -> 104458200000
B2: Cost of Debt | E2: Sources | G2: Debt | H2: 17031500000
B3: Risk-free (10-year Treasury) | D3: 0.04349 | E3: Bloomberg
B4: Cost of Debt | D4: =I8 -> 0.038811173 | E4: Calculated Avg | G4: Bond Maturity | H4: (YTM) | I4: Tax Rate
B5: Cost of Equity | G5: 2033 | H5: 0.049516 | I5: 0.24
B6: Risk-free (10-year Treasury) | D6: 0.04349 | G6: 2034 | H6: 0.050587 | I6: 0.24
B7: Tax rate | D7: 0.24 | G7: 2035 | H7: 0.053099 | I7: 0.24
B8: Debt/(Debt+Equity) | D8: =H2/(H1+H2) -> 0.14018884 | E8: Calculated | H8: Average | I8: =AVERAGE(H5:H7)*(1-I5) -> 0.038811173
B9: Equity risk premium | D9: 0.0451 | E9: Calculated Avg
B10: Equity Beta | D10: 0.82904772 | E10: Calucated by Regression pst 10 years | G10: Country | H10: Weight(%) by Region sales | I10: ERP (%) | J10: Weighted ERP
B11: Cost of Equity | D11: =D6+(D10*D9) -> 0.080880052 | G11: US | H11: 0.738 | I11: 0.0433 | J11: 0.031955
B12: Growth Rate | D12: 0.03045 | E12: Avg calculated | G12: China | H12: 0.083 | I12: 0.0527 | J12: 0.004374
B13: WACC | D13: =(D8*D4)+((1-D8)*D11) -> 0.074982465 | G13: Canada | H13: 0.06 | I13: 0.0433 | J13: 0.002598
G14: Japan | H14: 0.06 | I14: 0.0527 | J14: 0.003162
G15: UK | H15: 0.059 | I15: 0.0513 | J15: 0.003027
B16: After-Tax Cost of Debt=YTM⋅(1−Tax Rate) | H16: Total Weighted ERP | J16: =SUM(J11:J15) -> 0.045116
G19: Region | H19: Weight (Revenue %) | I19: Forecasted Real GDP Growth | J19: Weighted Growth
G20: USA | H20: 0.6 | I20: 0.02 | J20: =I20*H20 -> 0.012
G21: China | H21: 0.25 | I21: 0.04 | J21: =I21*H21 -> 0.01
G22: India | H22: 0.1 | I22: 0.063 | J22: =I22*H22 -> 0.0063
G23: UAE | H23: 0.05 | I23: 0.043 | J23: =I23*H23 -> 0.00215
H24: Weigth terminal Growth Rate | J24: =SUM(J20:J23) -> 0.03045

Sheet Beta Regression
N1: Date | O1: SBUX | P1: SPX | R1: SBUX RETURNS | S1: SPX RETURNS
A2: SUMMARY OUTPUT | N2: 45657 | O2: 91.25 | P2: 5881.63 | R2: =LN(O3/O2) -> 0.11586949 | S2: =LN(P3/P2) -> 0.025307692
N3: 45625 | O3: 102.46 | P3: 6032.38 | R3: =LN(O4/O3) -> -0.047570919 | S3: =LN(P4/P3) -> -0.055719768
A4: Regression Statistics | N4: 45596 | O4: 97.7 | P4: 5705.45 | R4: =LN(O5/O4) -> -0.0021517504 | S4: =LN(P5/P4) -> 0.0099460792
A5: Multiple R | B5: 0.53451543 | N5: 45565 | O5: 97.49 | P5: 5762.48 | R5: =LN(O6/O5) -> -0.030409508 | S5: =LN(P6/P5) -> -0.019995618
A6: R Square | B6: 0.28570675 | N6: 45534 | O6: 94.57 | P6: 5648.4 | R6: =LN(O7/O6) -> -0.19327271 | S6: =LN(P7/P6) -> -0.022577879
A7: Adjusted R Square | B7: 0.28003775 | N7: 45504 | O7: 77.95 | P7: 5522.3 | R7: =LN(O8/O7) -> -0.0012836972 | S7: =LN(P8/P7) -> -0.011257742
A8: Standard Error | B8: 0.056827586 | N8: 45471 | O8: 77.85 | P8: 5460.48 | R8: =LN(O9/O8) -> 0.029988962 | S8: =LN(P9/P8) -> -0.034082302
A9: Observations | B9: 128 | N9: 45443 | O9: 80.22 | P9: 5277.51 | R9: =LN(O10/O9) -> 0.098116691 | S9: =LN(P10/P9) -> -0.046903838
N10: 45412 | O10: 88.49 | P10: 5035.69 | R10: =LN(O11/O10) -> 0.032246512 | S10: =LN(P11/P10) -> 0.042505747
A11: ANOVA | N11: 45380 | O11: 91.39 | P11: 5254.35 | R11: =LN(O12/O11) -> 0.037687642 | S11: =LN(P12/P11) -> -0.030547405
B12: df | C12: SS | D12: MS | E12: F | F12: Significance F | N12: 45351 | O12: 94.9 | P12: 5096.27 | R12: =LN(O13/O12) -> -0.019901684 | S12: =LN(P13/P12) -> -0.050427504
A13: Regression | B13: 1 | C13: 0.16275446 | D13: 0.16275446 | E13: 50.398138 | F13: 8.1104662e-11 | N13: 45322 | O13: 93.03 | P13: 4845.65 | R13: =LN(O14/O13) -> 0.031530331 | S13: =LN(P14/P13) -> -0.01577073
A14: Residual | B14: 126 | C14: 0.40690119 | D14: 0.0032293745 | N14: 45289 | O14: 96.01 | P14: 4769.83 | R14: =LN(O15/O14) -> 0.033693218 | S14: =LN(P15/P14) -> -0.043278976
A15: Total | B15: 127 | C15: 0.56965565 | N15: 45260 | O15: 99.3 | P15: 4567.8 | R15: =LN(O16/O15) -> -0.073751695 | S15: =LN(P16/P15) -> -0.085424444
N16: 45230 | O16: 92.24 | P16: 4193.8 | R16: =LN(O17/O16) -> -0.010571729 | S16: =LN(P17/P16) -> 0.02222484
B17: Coefficients | C17: Standard Error | D17: t Stat | E17: P-value | F17: Lower 95% | G17: Upper 95% | H17: Lower 95.0% | I17: Upper 95.0% | N17: 45198 | O17: 91.27 | P17: 4288.05 | R17: =LN(O18/O17) -> 0.065414657 | S17: =LN(P18/P17) -> 0.049946088
A18: Intercept | B18: -4.3721721e-05 | C18: 0.0051291659 | D18: -0.0085241386 | E18: 0.99321229 | F18: -0.01019419 | G18: 0.010106747 | H18: -0.01019419 | I18: 0.010106747 | N18: 45169 | O18: 97.44 | P18: 4507.66 | R18: =LN(O19/O18) -> 0.041511412 | S18: =LN(P19/P18) -> 0.017875247
A19: X Variable 1 | B19: 0.82904772 | C19: 0.11678103 | D19: 7.0991646 | E19: 8.1104662e-11 | F19: 0.5979415 | G19: 1.0601539 | H19: 0.5979415 | I19: 1.0601539 | N19: 45138 | O19: 101.57 | P19: 4588.96 | R19: =LN(O20/O19) -> -0.025022489 | S19: =LN(P20/P19) -> -0.030663933
N20: 45107 | O20: 99.06 | P20: 4450.38 | R20: =LN(O21/O20) -> -0.014438482 | S20: =LN(P21/P20) -> -0.06271891
N21: 45077 | O21: 97.64 | P21: 4179.83 | R21: =LN(O22/O21) -> 0.15745183 | S21: =LN(P22/P21) -> -0.0024792481
N22: 45044 | O22: 114.29 | P22: 4169.48 | R22: =LN(O23/O22) -> -0.093098959 | S22: =LN(P23/P22) -> -0.014536197
N23: 45016 | O23: 104.13 | P23: 4109.31 | R23: =LN(O24/O23) -> -0.019785341 | S23: =LN(P24/P23) -> -0.034451254
N24: 44985 | O24: 102.09 | P24: 3970.15 | R24: =LN(O25/O24) -> 0.066776685 | S24: =LN(P25/P24) -> 0.02645943
N25: 44957 | O25: 109.14 | P25: 4076.6 | R25: =LN(O26/O25) -> -0.095493447 | S25: =LN(P26/P25) -> -0.059921158
N26: 44925 | O26: 99.2 | P26: 3839.5 | R26: =LN(O27/O26) -> 0.029793663 | S26: =LN(P27/P26) -> 0.060781799
N27: 44895 | O27: 102.2 | P27: 4080.11 | R27: =LN(O28/O27) -> -0.16574734 | S27: =LN(P28/P27) -> -0.052357945
N28: 44865 | O28: 86.59 | P28: 3871.98 | R28: =LN(O29/O28) -> -0.027277079 | S28: =LN(P29/P28) -> -0.076834602
N29: 44834 | O29: 84.26 | P29: 3585.62 | R29: =LN(O30/O29) -> -0.0022574714 | S29: =LN(P30/P29) -> 0.098049199
N30: 44804 | O30: 84.07 | P30: 3955 | R30: =LN(O31/O30) -> 0.0084098808 | S30: =LN(P31/P30) -> 0.043367021
N31: 44771 | O31: 84.78 | P31: 4130.29 | R31: =LN(O32/O31) -> -0.10420787 | S31: =LN(P32/P31) -> -0.087201344
... N130: 41759 | O130: 35.31 | P130: 1883.95 | R130: =LN(O131/O130) -> #NUM! | S130: =LN(P131/P130) -> #NUM!

Sheet Sensitivity Analysis
K1: Enterpise Value | L1: =DCF!U51 -> 130718.57
K2: Share Price | L2: =DCF!U56 -> 102.60813
C3: Share Price | F3: WAAC | K3: Growth Rate | L3: =DCF!U46 -> 0.03045
C4: =S11 -> 0 | D4: =F4-0.5% -> 0.069982465 | E4: =F4-0.25% -> 0.072482465 | F4: 0.074982465 | G4: =F4+0.25% -> 0.077482465 | H4: =F4+0.5% -> 0.079982465 | K4: WACC | L4: =DCF!U47 -> 0.074982465
C5: =C7-0.5% -> 0.02545 | D5: 106.26528 | E5: 99.782849 | F5: 93.993099 | G5: 88.795265 | H5: 84.107084
C6: =C7-0.25% -> 0.02795 | D6: 111.55892 | E6: 104.41539 | F6: 98.071649 | G6: 92.405619 | H6: 87.318718
B7: Growth Rate | C7: 0.03045 | D7: 117.52209 | E7: 109.59901 | F7: 102.60813 | G7: 96.399787 | H7: 90.854547
C8: =C7+0.25% -> 0.03295 | D8: 124.29039 | E8: 115.43823 | F8: 107.68425 | G8: 100.84241 | H8: 94.766269
C9: =C7+0.5% -> 0.03545 | D9: 132.03868 | E9: 122.06585 | F9: 113.40239 | G9: 105.81351 | H9: 99.117189
C14: Enterprise Value | F14: WAAC
C15: =S6 -> 0 | D15: =E15-0.25% -> 0.069982465 | E15: =F15-0.25% -> 0.072482465 | F15: 0.074982465 | G15: =F15+0.25% -> 0.077482465 | H15: =G15+0.25% -> 0.079982465
C16: =C17-0.25% -> 0.02545 | D16: 134887.72 | E16: 127497.75 | F16: 120897.43 | G16: 114971.9 | H16: 109627.38
C17: =C18-0.25% -> 0.02795 | D17: 140922.47 | E17: 132778.85 | F17: 125546.98 | G17: 119087.71 | H17: 113288.64
B18: Growth Rate | C18: 0.03045 | D18: 147720.49 | E18: 138688.17 | F18: 130718.57 | G18: 123641.06 | H18: 117319.48
C19: =C18+0.25% -> 0.03295 | D19: 155436.35 | E19: 145344.89 | F19: 136505.35 | G19: 128705.65 | H19: 121778.85
C20: =C19+0.25% -> 0.03545 | D20: 164269.39 | E20: 152900.37 | F20: 143024.03 | G20: 134372.7 | H20: 126738.9

Sheet Adjusted Tax Rate 
B3: Calcualtion | C3: 2015 | D3: =+C3+1 -> 2016 | E3: =+D3+1 -> 2017 | F3: =+E3+1 -> 2018 | G3: =+F3+1 -> 2019 | H3: =+G3+1 -> 2020 | I3: =+H3+1 -> 2021 | J3: =+I3+1 -> 2022 | K3: =+J3+1 -> 2023 | L3: =+K3+1 -> 2024
B4: Fed Statutory rate | C4: 0.35 | D4: 0.35 | E4: 0.35 | F4: 0.245 | G4: 0.21 | H4: 0.21 | I4: 0.21 | J4: 0.21 | K4: 0.21 | L4: 0.21
B6: Interest Tax Shield | C6: ='Income Statement'!B39*'Adjusted Tax Rate '!C4 -> 24.675 | D6: ='Income Statement'!C39*'Adjusted Tax Rate '!D4 -> 28.455 | E6: ='Income Statement'!D39*'Adjusted Tax Rate '!E4 -> 32.375 | F6: ='Income Statement'!E39*'Adjusted Tax Rate '!F4 -> 41.7235 | G6: ='Income Statement'!F39*'Adjusted Tax Rate '!G4 -> 69.51 | H6: ='Income Statement'!G39*'Adjusted Tax Rate '!H4 -> 91.77 | I6: ='Income Statement'!H39*'Adjusted Tax Rate '!I4 -> 98.658 | J6: ='Income Statement'!I39*'Adjusted Tax Rate '!J4 -> 101.409 | ... L6: ='Income Statement'!K39*'Adjusted Tax Rate '!L4 -> 118.02
B7: Adjusted Tax Rate | C7: =C9/DCF!B22 -> 0.31961238 | D7: =D9/DCF!C22 -> 0.33753326 | E7: =E9/DCF!D22 -> 0.33668298 | F7: =F9/DCF!E22 -> 0.2900386 | G7: =G9/DCF!F22 -> 0.20590964 | H7: =H9/DCF!G22 -> 0.15538627 | I7: =I9/DCF!H22 -> 0.24056766 | J7: =J9/DCF!I22 -> 0.21625314 | ... L7: =L9/DCF!K22 -> 0.23964704
B9: Adjusted Tax Expense | C9: ='Income Statement'!B67+'Adjusted Tax Rate '!C6 -> 1168.375 | D9: ='Income Statement'!C67+'Adjusted Tax Rate '!D6 -> 1408.155 | E9: ='Income Statement'!D67+'Adjusted Tax Rate '!E6 -> 1464.975 | F9: ='Income Statement'!E67+'Adjusted Tax Rate '!F6 -> 1303.7235 | G9: ='Income Statement'!F67+'Adjusted Tax Rate '!G6 -> 941.11 | H9: ='Income Statement'!G67+'Adjusted Tax Rate '!H6 -> 331.47 | I9: ='Income Statement'!H67+'Adjusted Tax Rate '!I6 -> 1255.258 | J9: ='Income Statement'!I67+'Adjusted Tax Rate '!J6 -> 1049.909 | ... L9: ='Income Statement'!K67+'Adjusted Tax Rate '!L6 -> 1325.32
B10: 1. Interest Tax Shield=Interest Expense×Statutory Corporate Tax Rate
B11: 2.Adjusted Tax Expense=Reported Tax Expense+Interest Tax Shield
B12: 3. Adjusted Tax Rate= Adjusted Tax Expense/EBIT
I14: Tax Expense+(Interest Expense×Corporate Tax Rate)/EBIT ​

Sheet DCF
E1: STARBUCKS US (SBUX) DFC Model
A3: Overview
A4: Company Ticker | B4: SBUX
A5: Date | B5: 45868
A6: Stock Price | B6: 91.63
A7: Stock Price Forecast | B7: =U56 -> 102.60813
A8: Delta | B8: =B7/B6-1 -> 0.11980934
B10: 2015 | C10: =+B10+1 -> 2016 | D10: =+C10+1 -> 2017 | E10: =+D10+1 -> 2018 | F10: =+E10+1 -> 2019 | G10: =+F10+1 -> 2020 | H10: =+G10+1 -> 2021 | I10: =+H10+1 -> 2022 | J10: =+I10+1 -> 2023 | ... U10: =+T10+1 -> 2034 | V10: CAGR 2015-24 | W10: CAGR 2025-34
A12: Revenue | B12: ='Income Statement'!B6 -> 19162.7 | C12: ='Income Statement'!C6 -> 21315.9 | D12: ='Income Statement'!D6 -> 22386.8 | E12: ='Income Statement'!E6 -> 24719.5 | F12: ='Income Statement'!F6 -> 26508.6 | G12: ='Income Statement'!G6 -> 23518 | H12: ='Income Statement'!H6 -> 29060.6 | I12: ='Income Statement'!I6 -> 32250.3 | ... K12: ='Income Statement'!K6 -> 36176.2 | L12: ='growth calculation'!I10 -> 37248.588 | M12: ='growth calculation'!J10 -> 38415.425 | N12: ='growth calculation'!K10 -> 39639.76 | O12: ='growth calculation'!L10 -> 40904.632 | P12: ='growth calculation'!M10 -> 42211.43 | Q12: ='growth calculation'!N10 -> 43674.011 | R12: ='growth calculation'!O10 -> 45192.405 | S12: ='growth calculation'!P10 -> 46768.962 | ... U12: ='growth calculation'!R10 -> 50106.501 | V12: =(K12/B12)^(1/9)-1 -> 0.073156144 | W12: =(U12/L12)^(1/9)-1 -> 0.033497338
A13: % of growth | C13: =C12/B12-1 -> 0.11236412 | D13: =D12/C12-1 -> 0.050239493 | E13: =E12/D12-1 -> 0.1041998 | F13: =F12/E12-1 -> 0.072376059 | G13: =G12/F12-1 -> -0.11281622 | H13: =H12/G12-1 -> 0.2356748 | I13: =I12/H12-1 -> 0.10976029 | J13: =J12/I12-1 -> 0.1155121 | ... U13: =U12/T12-1 -> 0.035127011
A14: Cogs | B14: ='Income Statement'!B14 -> 13198.6 | C14: ='Income Statement'!C14 -> 14573.3 | D14: ='Income Statement'!D14 -> 15552.2 | E14: ='Income Statement'!E14 -> 17402.9 | F14: ='Income Statement'!F14 -> 19020.5 | G14: ='Income Statement'!G14 -> 18458.9 | H14: ='Income Statement'!H14 -> 20652 | I14: ='Income Statement'!I14 -> 23879.2 | ... K14: ='Income Statement'!K14 -> 26467.1 | L14: =L12*L15 -> 26818.983 | M14: =M12*M15 -> 27274.952 | N14: =N12*N15 -> 28144.23 | O14: =O12*O15 -> 29042.289 | P14: =P12*P15 -> 29970.116 | Q14: =Q12*Q15 -> 30135.067 | R14: =R12*R15 -> 31182.76 | S14: =S12*S15 -> 32270.584 | ... U14: =U12*U15 -> 34072.421
A15: % of revenue | B15: =(B14/B12) -> 0.68876515 | C15: =(C14/C12) -> 0.68368213 | D15: =(D14/D12) -> 0.69470402 | E15: =(E14/E12) -> 0.70401505 | F15: =(F14/F12) -> 0.71752186 | G15: =(G14/G12) -> 0.78488392 | H15: =(H14/H12) -> 0.71065291 | I15: =(I14/I12) -> 0.74043342 | ... K15: =(K14/K12) -> 0.73161637 | L15: 0.72 | M15: 0.71 | N15: 0.71 | O15: 0.71 | P15: 0.71 | Q15: 0.69 | R15: 0.69 | S15: 0.69 | T15: 0.68 | U15: 0.68
A16: Gross Profit | B16: =B12-B14 -> 5964.1 | C16: =C12-C14 -> 6742.6 | D16: =D12-D14 -> 6834.6 | E16: =E12-E14 -> 7316.6 | F16: =F12-F14 -> 7488.1 | G16: =G12-G14 -> 5059.1 | H16: =H12-H14 -> 8408.6 | I16: =I12-I14 -> 8371.1 | ... U16: =U12-U14 -> 16034.08 | V16: =(K16/B16)^(1/9)-1 -> 0.055637708 | W16: =(U16/L16)^(1/9)-1 -> 0.048945471
A17: % of revenue | B17: =(B16/B12) -> 0.31123485 | C17: =(C16/C12) -> 0.31631787 | D17: =(D16/D12) -> 0.30529598 | E17: =(E16/E12) -> 0.29598495 | F17: =(F16/F12) -> 0.28247814 | G17: =(G16/G12) -> 0.21511608 | H17: =(H16/H12) -> 0.28934709 | I17: =(I16/I12) -> 0.25956658 | ... U17: =(U16/U12) -> 0.32
A18: Other Operating Income | B18: ='Income Statement'!B18 -> 0 | C18: ='Income Statement'!C18 -> 318.2 | D18: ='Income Statement'!D18 -> 391.4 | E18: ='Income Statement'!E18 -> 301.2 | F18: ='Income Statement'!F18 -> 298 | G18: ='Income Statement'!G18 -> 322.5 | H18: ='Income Statement'!H18 -> 385.3 | I18: ='Income Statement'!I18 -> 234.1 | ... K18: ='Income Statement'!K18 -> 301.2 | L18: =L12*L19 -> 372.48588 | M18: =M12*M19 -> 384.15425 | N18: =N12*N19 -> 396.3976 | O18: =O12*O19 -> 409.04632 | P18: =P12*P19 -> 422.1143 | Q18: =Q12*Q19 -> 436.74011 | R18: =R12*R19 -> 451.92405 | S18: =S12*S19 -> 467.68962 | ... U18: =U12*U19 -> 501.06501
A19: % of revenue | B19: =(B18/B12) -> 0 | C19: =(C18/C12) -> 0.014927824 | D19: =(D18/D12) -> 0.017483517 | E19: =(E18/E12) -> 0.012184712 | F19: =(F18/F12) -> 0.011241635 | G19: =(G18/G12) -> 0.013712901 | H19: =(H18/H12) -> 0.013258501 | I19: =(I18/I12) -> 0.0072588472 | ... K19: =(K18/K12) -> 0.0083259159 | L19: 0.01 | M19: 0.01 | N19: 0.01 | O19: 0.01 | P19: 0.01 | Q19: 0.01 | R19: 0.01 | S19: 0.01 | T19: 0.01 | U19: 0.01
A20: Operating Expenses | B20: ='Income Statement'!B20 -> 2308.5 | C20: ='Income Statement'!C20 -> 2888.9 | D20: ='Income Statement'!D20 -> 2874.8 | E20: ='Income Statement'!E20 -> 3122.8 | F20: ='Income Statement'!F20 -> 3215.6 | G20: ='Income Statement'!G20 -> 3248.4 | H20: ='Income Statement'!H20 -> 3576 | I20: ='Income Statement'!I20 -> 3750.2 | ... K20: ='Income Statement'!K20 -> 4480 | L20: =L12*L21 -> 4656.0735 | M20: =M12*M21 -> 4801.9281 | N20: =N12*N21 -> 4954.97 | O20: =O12*O21 -> 4908.5559 | P20: =P12*P21 -> 5065.3716 | Q20: =Q12*Q21 -> 5240.8813 | R20: =R12*R21 -> 4971.1646 | S20: =S12*S21 -> 5144.5859 | ... U20: =U12*U21 -> 5511.7151
A21: % of revenue | B21: =(B20/B12) -> 0.12046841 | C21: =(C20/C12) -> 0.13552794 | D21: =(D20/D12) -> 0.12841496 | E21: =(E20/E12) -> 0.12632942 | F21: =(F20/F12) -> 0.12130403 | G21: =(G20/G12) -> 0.13812399 | H21: =(H20/H12) -> 0.12305321 | I21: =(I20/I12) -> 0.11628419 | ... K21: =(K20/K12) -> 0.12383832 | L21: 0.125 | M21: 0.125 | N21: 0.125 | O21: 0.12 | P21: 0.12 | Q21: 0.12 | R21: 0.11 | S21: 0.11 | T21: 0.11 | U21: 0.11 | AF21: equity | AG21: =1140000000*DCF!B6 -> 104458200000
A22: EBIT | B22: =(B16+B18)-B20 -> 3655.6 | C22: =(C16+C18)-C20 -> 4171.9 | D22: =(D16+D18)-D20 -> 4351.2 | E22: =(E16+E18)-E20 -> 4495 | F22: =(F16+F18)-F20 -> 4570.5 | G22: =(G16+G18)-G20 -> 2133.2 | H22: =(H16+H18)-H20 -> 5217.9 | I22: =(I16+I18)-I20 -> 4855 | ... U22: =(U16+U18)-U20 -> 11023.43 | V22: =(K22/B22)^(1/9)-1 -> 0.047072296 | W22: =(U22/L22)^(1/9)-1 -> 0.067066398 | AF22: debt | AG22: 17031500000
A23: % of revenue | B23: =B22/B12 -> 0.19076644 | C23: =C22/C12 -> 0.19571775 | D23: =D22/D12 -> 0.19436454 | E23: =E22/E12 -> 0.18184025 | F23: =F22/F12 -> 0.17241574 | G23: =G22/G12 -> 0.090704992 | H23: =H22/H12 -> 0.17955238 | I23: =I22/I12 -> 0.15054124 | ... U23: =U22/U12 -> 0.22
A25: Taxes | B25: ='Adjusted Tax Rate '!C9 -> 1168.375 | C25: ='Adjusted Tax Rate '!D9 -> 1408.155 | D25: ='Adjusted Tax Rate '!E9 -> 1464.975 | E25: ='Adjusted Tax Rate '!F9 -> 1303.7235 | F25: ='Adjusted Tax Rate '!G9 -> 941.11 | G25: ='Adjusted Tax Rate '!H9 -> 331.47 | H25: ='Adjusted Tax Rate '!I9 -> 1255.258 | I25: ='Adjusted Tax Rate '!J9 -> 1049.909 | ... K25: ='Adjusted Tax Rate '!L9 -> 1325.32 | L25: =L22*L26 -> 1475.0441 | M25: =M22*M26 -> 1613.4478 | N25: =N22*N26 -> 1664.8699 | O25: =O22*O26 -> 1767.0801 | P25: =P22*P26 -> 1823.5338 | Q25: =Q22*Q26 -> 2096.3525 | R25: =R22*R26 -> 2277.6972 | S25: =S22*S26 -> 2357.1557 | ... U25: =U22*U26 -> 2645.6232
A26: %Effective tax rate | B26: =B25/B22 -> 0.31961238 | C26: =C25/C22 -> 0.33753326 | D26: =D25/D22 -> 0.33668298 | E26: =E25/E22 -> 0.2900386 | F26: =F25/F22 -> 0.20590964 | G26: =G25/G22 -> 0.15538627 | H26: =H25/H22 -> 0.24056766 | I26: =I25/I22 -> 0.21625314 | ... K26: =K25/K22 -> 0.23964704 | L26: 0.24 | M26: 0.24 | N26: 0.24 | O26: 0.24 | P26: 0.24 | Q26: 0.24 | R26: 0.24 | S26: 0.24 | T26: 0.24 | U26: 0.24 | AA26: WACC Calculation
AA27: Cost of Debt | AD27: Sources
A28: EBIAT | B28: =B22*(1-B26) -> 2487.225 | C28: =C22*(1-C26) -> 2763.745 | D28: =D22*(1-D26) -> 2886.225 | E28: =E22*(1-E26) -> 3191.2765 | F28: =F22*(1-F26) -> 3629.39 | G28: =G22*(1-G26) -> 1801.73 | H28: =H22*(1-H26) -> 3962.642 | I28: =I22*(1-I26) -> 3805.091 | ... U28: =U22*(1-U26) -> 8377.807 | V28: =(K28/B28)^(1/9)-1 -> 0.060080296 | W28: =(U28/L28)^(1/9)-1 -> 0.067066398 | AA28: Risk-free (10-year Treasury) | AC28: 0.04349 | AD28: Bloomberg
A29: % of revenue | B29: =B28/B12 -> 0.12979512 | C29: =C28/C12 -> 0.1296565 | D29: =D28/D12 -> 0.1289253 | E29: =E28/E12 -> 0.12909956 | F29: =F28/F12 -> 0.13691368 | G29: =G28/G12 -> 0.076610681 | H29: =H28/H12 -> 0.13635789 | I29: =I28/I12 -> 0.11798622 | ... U29: =U28/U12 -> 0.1672 | AA29: Cost of Debt | AC29: =AH34 -> 0.038811173 | AD29: Calculated Avg | AF29: cost of debt
AA30: Cost of Equity | AF30: Bond Maturity | AG30: (YTM) | AH30: Tax Rate
A31: Plus: D&A | B31: ='Income Statement'!B29 -> 893.9 | C31: ='Income Statement'!C29 -> 980.8 | D31: ='Income Statement'!D29 -> 1011.4 | E31: ='Income Statement'!E29 -> 1247 | F31: ='Income Statement'!F29 -> 1377.3 | G31: ='Income Statement'!G29 -> 1431.3 | H31: ='Income Statement'!H29 -> 1441.7 | I31: ='Income Statement'!I29 -> 1447.9 | ... K31: ='Income Statement'!K29 -> 1512.6 | L31: =L12*L32 -> 1676.1865 | M31: =M12*M32 -> 1728.6941 | N31: =N12*N32 -> 1783.7892 | O31: =O12*O32 -> 1840.7085 | P31: =P12*P32 -> 1688.4572 | Q31: =Q12*Q32 -> 1746.9604 | R31: =R12*R32 -> 1581.7342 | S31: =S12*S32 -> 1636.9137 | T31: =T12*T32 -> 1694.2148 | U31: =U34 -> 1801.3006 | AA31: Risk-free (10-year Treasury) | AC31: 0.04349 | AF31: 2033 | AG31: 0.049516 | AH31: 0.24
A32: % of revenue | B32: =B31/B12 -> 0.046647915 | C32: =C31/C12 -> 0.046012601 | D32: =D31/D12 -> 0.045178409 | E32: =E31/E12 -> 0.050446004 | F32: =F31/F12 -> 0.051956723 | G32: =G31/G12 -> 0.060859767 | H32: =H31/H12 -> 0.049610125 | I32: =I31/I12 -> 0.044895706 | ... K32: =K31/K12 -> 0.04181202 | L32: 0.045 | M32: 0.045 | N32: 0.045 | O32: 0.045 | P32: 0.04 | Q32: 0.04 | R32: 0.035 | S32: 0.035 | T32: 0.035 | U32: =U31/U12 -> 0.035949439 | AA32: Tax rate | AC32: 0.24 | AF32: 2034 | AG32: 0.050587 | AH32: 0.24
AA33: Debt/(Debt+Equity) | AC33: =AG22/(AG22+AG21) -> 0.14018884 | AD33: Calculated | AF33: 2035 | AG33: 0.053099 | AH33: 0.24
A34: Less: Capex | B34: =-('Cash Flow '!B33) -> 1303.7 | C34: =-('Cash Flow '!C33) -> 1440.3 | D34: =-('Cash Flow '!D33) -> 1519.4 | E34: =-('Cash Flow '!E33) -> 1976.4 | F34: =-('Cash Flow '!F33) -> 1806.6 | G34: =-('Cash Flow '!G33) -> 1483.6 | H34: =-('Cash Flow '!H33) -> 1470 | I34: =-('Cash Flow '!I33) -> 1841.3 | ... K34: =-('Cash Flow '!K33) -> 2777.5 | L34: ='growth calculation'!I53 -> 2907.5093 | M34: ='growth calculation'!J53 -> 2329.6152 | N34: ='growth calculation'!K53 -> 2414.3219 | O34: ='growth calculation'!L53 -> 1878.5481 | P34: ='growth calculation'!M53 -> 2447.3848 | Q34: ='growth calculation'!N53 -> 2587.4356 | R34: ='growth calculation'!O53 -> 2679.8745 | S34: ='growth calculation'!P53 -> 2191.3475 | ... U34: ='growth calculation'!R53 -> 1801.3006 | AA34: Equity risk premium | AC34: 0.0451 | AD34: Calculated Avg | AG34: Average | AH34: =AVERAGE(AG31:AG33)*(1-AH31) -> 0.038811173
A35: % of revenue | B35: =B34/B12 -> 0.06803321 | C35: =C34/C12 -> 0.067569279 | D35: =D34/D12 -> 0.067870352 | E35: =E34/E12 -> 0.079953073 | F35: =F34/F12 -> 0.068151468 | G35: =G34/G12 -> 0.063083596 | H35: =H34/H12 -> 0.050583952 | I35: =I34/I12 -> 0.057094043 | ... U35: =U34/U12 -> 0.035949439 | AA35: Equity Beta | AC35: 0.82904772 | AD35: Calucated by Regression pst 10 years
AA36: Cost of Equity | AC36: =AC31+(AC35*AC34) -> 0.080880052
A37: Net Working Capital | B37: ='growth calculation'!C80 -> 416 | C37: ='growth calculation'!D80 -> 321.8 | D37: ='growth calculation'!E80 -> 281.9 | E37: ='growth calculation'!F80 -> 723.8 | F37: ='growth calculation'!G80 -> 425.5 | G37: ='growth calculation'!H80 -> 347.4 | H37: ='growth calculation'!I80 -> 162.5 | I37: ='growth calculation'!J80 -> 788.9 | ... K37: ='growth calculation'!L80 -> -77.3 | L37: =L12*L38 -> 297.9887 | M37: =M12*M38 -> 307.3234 | N37: =N12*N38 -> 356.75784 | O37: =O12*O38 -> 409.04632 | P37: =P12*P38 -> 422.1143 | Q37: =Q12*Q38 -> 524.08813 | R37: =R12*R38 -> 542.30886 | S37: =S12*S38 -> 561.22755 | ... U37: =U12*U38 -> 701.49101 | AA37: Growth Rate | AC37: 0.03045 | AD37: Avg calculated
A38: % of revenue | B38: =B37/B12 -> 0.021708841 | C38: =C37/C12 -> 0.015096712 | D38: =D37/D12 -> 0.012592242 | E38: =E37/E12 -> 0.029280528 | F38: =F37/F12 -> 0.016051395 | G38: =G37/G12 -> 0.014771664 | H38: =H37/H12 -> 0.0055917634 | I38: =I37/I12 -> 0.024461788 | ... K38: =K37/K12 -> -0.0021367639 | L38: 0.008 | M38: 0.008 | N38: 0.009 | O38: 0.01 | P38: 0.01 | Q38: 0.012 | R38: 0.012 | S38: 0.012 | T38: 0.013 | U38: 0.014 | AA38: WACC | AC38: =(AC33*AC29)+((1-AC33)*AC36) -> 0.074982465 | AF38: Country | AG38: Weight(%) by Region sales | AH38: ERP (%) | AI38: Weighted ERP
A39: Less: Change in NWC | C39: ='growth calculation'!D82 -> -94.2 | D39: ='growth calculation'!E82 -> -39.9 | E39: ='growth calculation'!F82 -> 441.9 | F39: ='growth calculation'!G82 -> -298.3 | G39: ='growth calculation'!H82 -> -78.1 | H39: ='growth calculation'!I82 -> -184.9 | I39: ='growth calculation'!J82 -> 626.4 | J39: ='growth calculation'!K82 -> -724 | K39: ='growth calculation'!L82 -> -142.2 | L39: =L37-K37 -> 375.2887 | M39: =M37-L37 -> 9.334696 | N39: =N37-M37 -> 49.434443 | O39: =O37-N37 -> 52.288481 | P39: =P37-O37 -> 13.06798 | Q39: =Q37-P37 -> 101.97382 | R39: =R37-Q37 -> 18.220736 | S39: =S37-R37 -> 18.918686 | ... U39: =U37-T37 -> 72.211219 | AF39: US | AG39: 0.738 | AH39: 0.0433 | AI39: 0.031955
AF40: China | AG40: 0.083 | AH40: 0.0527 | AI40: 0.004374
A41: Unlevered FCF | B41: =B28+B31-B34-B39 -> 2077.425 | C41: =C28+C31-C34-C39 -> 2398.445 | D41: =D28+D31-D34-D39 -> 2418.125 | E41: =E28+E31-E34-E39 -> 2019.9765 | F41: =F28+F31-F34-F39 -> 3498.39 | G41: =G28+G31-G34-G39 -> 1827.53 | H41: =H28+H31-H34-H39 -> 4119.242 | I41: =I28+I31-I34-I39 -> 2785.291 | ... U41: =U28+U31-U34-U39 -> 8305.5957 | V41: =(K41/B41)^(1/9)-1 -> 0.0448129 | W41: =(U41/L41)^(1/9)-1 -> 0.11715783 | AF41: Canada | AG41: 0.06 | AH41: 0.0433 | AI41: 0.002598
AF42: Japan | AG42: 0.06 | AH42: 0.0527 | AI42: 0.003162
J43: Discount Period | L43: =1 -> 1 | M43: =L43+1 -> 2 | N43: =M43+1 -> 3 | O43: =N43+1 -> 4 | P43: =O43+1 -> 5 | Q43: =P43+1 -> 6 | R43: =Q43+1 -> 7 | S43: =R43+1 -> 8 | T43: =S43+1 -> 9 | U43: =T43+1 -> 10 | AF43: UK | AG43: 0.059 | AH43: 0.0513 | AI43: 0.003027
J44: Discounted FCF | L44: =L41/(1+$AC38)^L43 -> 2850.6153 | M44: =M41/(1+$AC38)^M43 -> 3893.2548 | N44: =N41/(1+$AC38)^N43 -> 3696.6572 | O44: =O41/(1+$AC38)^O43 -> 4122.8844 | P44: =P41/(1+$AC38)^P43 -> 3484.8384 | Q44: =Q41/(1+$AC38)^Q43 -> 3691.1505 | R44: =R41/(1+$AC38)^R43 -> 3675.0225 | S44: =S41/(1+$AC38)^S43 -> 3864.2887 | T44: =T41/(1+$AC38)^T43 -> 4146.8479 | U44: =U41/(1+U47)^U43 -> 4030.482 | AG44: Total Weighted ERP | AI44: =SUM(AI39:AI43) -> 0.045116
...

Sheet Ratios 
L1: Starbucks Corp (SBUX US) - PR | Q1: Company | R1: P/E Ratio=Share Price/EPS | S1: EV/EBITDA = Enterprise Value/EBITDA | T1: EV/EBIT= Enterprise Value/EBIT | U1: EV/REVENUE = Enterprise Value/Revenue
B2: P/E Ratio | C2: 2023 | D2: 2024 | L2: In Millions of USD except Per Share | M2: FY 2023 | N2: FY 2024
B3: Starbucks | C3: =M4 -> 25.68 | D3: =N4 -> 28.68 | L3: 12 Months Ending | M3: 44936 | N3: 09/29/2024
B4: Peers Average | C4: =AVERAGE(C8:C13) -> 42.216667 | D4: =AVERAGE(D8:D13) -> 38.583333 | L4: P/E | M4: 25.68 | N4: 28.68
B5: Deviations | C5: =(C3-C4)/C4 -> -0.39170944 | D5: =(D3-D4)/D4 -> -0.25667387 | L5: EV/EBIT= Enterprise Value/EBIT | M5: =M11/M8 -> 21.324947 | N5: =N11/N8 -> 24.514791
L6: EV/REVENUE = Enterprise Value/Revenue | M6: =M11/M10 -> 3.4799837 | N6: =N11/N10 -> 3.6652716
L7: EV/EBITDA = Enterprise Value/EBITDA | M7: =M11/M9 -> 14.031954 | N7: =N11/N9 -> 15.197726
B8: McDonald's Crop | C8: =M16 -> 25.1 | D8: =N16 -> 24.8 | L8: EBIT | M8: 5870.8 | N8: 5408.8
B9: Chipotle Mexican Grill Inc | C9: =M29 -> 50.1 | D9: =N29 -> 53.3 | L9: EBITDA | M9: 8922.1 | N9: 8724.7
B10: Yum! Brands Inc | C10: =M42 -> 25.3 | D10: =N42 -> 24.9 | L10: Revenue | M10: 35975.6 | N10: 36176.2
B11: Restaurant Brands International Inc | C11: =M55 -> 29.1 | D11: =N55 -> 31.4 | L11: Enterprise Value | M11: 125194.5 | N11: 132595.6
B12: Yum china Holding Inc | C12: =M69 -> 20.4 | D12: =N69 -> 20.5
B13: Wingstop Inc | C13: =M81 -> 103.3 | D13: =N81 -> 76.6 | L13: McDonald's Corp (MCD US) - PR
L14: In Millions of USD except Per Share | M14: FY 2023 | N14: FY 2024
L15: 12 Months Ending | M15: 12/31/2023 | N15: 12/31/2024
L16: P/E | M16: 25.1 | N16: 24.8
B17: EV/EBIT | C17: 2023 | D17: 2024 | L17: EV/EBIT= Enterprise Value/EBIT | M17: =M23/M20 -> 22.631561 | N17: =N23/N20 -> 22.080251
B18: Starbucks | C18: =M5 -> 21.324947 | D18: =N5 -> 24.514791 | L18: EV/REVENUE = Enterprise Value/Revenue | M18: =M23/M22 -> 10.339143 | N18: =N23/N22 -> 9.9770023
B19: Peers Average | C19: =AVERAGE(C23:C28) -> 33.119748 | D19: =AVERAGE(D23:D28) -> 29.76868 | L19: EV/EBITDA = Enterprise Value/EBITDA | M19: =M23/M21 -> 17.378488 | N19: =N23/N21 -> 16.802281
B20: Deviations | C20: =(C18-C19)/C19 -> -0.35612593 | D20: =(D18-D19)/D19 -> -0.17649051 | L20: EBIT | M20: 11646.7 | N20: 11712
L21: EBITDA | M21: 15167.2 | N21: 15391
L22: Revenue | M22: 25493.7 | N22: 25920
B23: McDonald's Crop | C23: =M17 -> 22.631561 | D23: =N17 -> 22.080251 | L23: Enterprise Value | M23: 263583 | N23: 258603.9
B24: Chipotle Mexican Grill Inc | C24: =M30 -> 42.059956 | D24: =N30 -> 44.503522
B25: Yum! Brands Inc | C25: =M43 -> 20.769672 | D25: =N43 -> 20.437079
B26: Restaurant Brands International Inc | C26: =M56 -> 24.301909 | D26: =N56 -> 18.701277 | L26: Chipotle Mexican Grill Inc (CMG US) - PR
B27: Yum china Holding Inc | C27: =M70 -> 16.223599 | D27: =N70 -> 16.809639 | L27: In Millions of USD except Per Share | M27: FY 2023 | N27: FY 2024
B28: Wingstop Inc | C28: =M82 -> 72.731794 | D28: =N82 -> 56.080314 | L28: 12 Months Ending | M28: 12/31/2023 | N28: 12/31/2024
L29: P/E | M29: 50.1 | N29: 53.3
L30: EV/EBIT= Enterprise Value/EBIT | M30: =M36/M33 -> 42.059956 | N30: =N36/N33 -> 44.503522
L31: EV/REVENUE = Enterprise Value/Revenue | M31: =M36/M35 -> 6.6373232 | N31: =N36/N35 -> 7.5378163
B32: EV/REVENUE | C32: 2023 | D32: 2024 | L32: EV/EBITDA = Enterprise Value/EBITDA | M32: =M36/M34 -> 28.378812 | N32: =N36/N34 -> 31.188597
B33: Starbucks | C33: =M6 -> 3.4799837 | D33: =N6 -> 3.6652716 | L33: EBIT | M33: 1557.8 | N33: 1916.3
B34: Peers Average | C34: =AVERAGE(C38:C43) -> 8.3808125 | D34: =AVERAGE(D38:D43) -> 7.6361131 | L34: EBITDA | M34: 2308.8 | N34: 2734.4
B35: Deviations | C35: =(C33-C34)/C34 -> -0.58476775 | D35: =(D33-D34)/D34 -> -0.5200082 | L35: Revenue | M35: 9871.6 | N35: 11313.9
L36: Enterprise Value | M36: 65521 | N36: 85282.1
B38: McDonald's Crop | C38: =M18 -> 10.339143 | D38: =N18 -> 9.9770023
B39: Chipotle Mexican Grill Inc | C39: =M31 -> 6.6373232 | D39: =N31 -> 7.5378163 | L39: Yum! Brands Inc (YUM US) - PR
B40: Yum! Brands Inc | C40: =M44 -> 6.8038581 | D40: =N44 -> 6.5055372 | L40: In Millions of USD except Per Share | M40: FY 2023 | N40: FY 2024
B41: Restaurant Brands International Inc | C41: =M57 -> 7.0704643 | D41: =N57 -> 5.2281704 | L41: 12 Months Ending | M41: 12/31/2023 | N41: 12/31/2024
...

Sheet growth calculation
B2: Primary Approach -Revenue Forecaste by Segmentation
B3: Region wise | C3: 2019 | D3: 2020 | E3: 2021 | F3: 2022 | G3: 2023 | H3: 2024 | I3: 2025 | J3: 2026 | K3: 2027 | L3: 2028 | M3: 2029 | N3: 2030 | O3: 2031 | P3: 2032 | Q3: 2033 | R3: 2034 | S3: CAGR 2019-24 | T3: CAGR 2021-24 | U3: CAGR 2025-34
B4: North America | C4: 18259 | D4: 16379.2 | E4: 20447.9 | F4: 23370.8 | G4: 26569.6 | H4: 27009.5 | I4: =H4+(H4*I5) -> 27819.785 | J4: =I4+(I4*J5) -> 28654.379 | K4: =J4+(J4*K5) -> 29514.01 | L4: =K4+(K4*L5) -> 30399.43 | M4: =L4+(L4*M5) -> 31311.413 | N4: =M4+(M4*N5) -> 32250.756 | O4: =N4+(N4*O5) -> 33218.278 | P4: =O4+(O4*P5) -> 34214.827 | ... R4: =Q4+(Q4*R5) -> 36298.509 | S4: =(H4/C4)^(1/4)-1 -> 0.10283335 | T4: =(H4/E4)^(1/3)-1 -> 0.097208788 | U4: =(R4/I4)^(1/9)-1 -> 0.03
B5: % YoY growth | D5: =(D4-C4)/C4 -> -0.10295197 | E5: =(E4-D4)/D4 -> 0.24840652 | F5: =(F4-E4)/E4 -> 0.14294377 | G5: =(G4-F4)/F4 -> 0.13687165 | H5: =(H4-G4)/G4 -> 0.016556516 | I5: 0.03 | J5: 0.03 | K5: 0.03 | L5: 0.03 | M5: 0.03 | N5: 0.03 | O5: 0.03 | P5: 0.03 | Q5: 0.03 | R5: 0.03
B6: International | C6: 6190.7 | D6: 5147.6 | E6: 6921.6 | F6: 6940.1 | G6: 7487.6 | H6: 7338.9 | I6: =H6+(H6*I7) -> 7632.456 | J6: =I6+(I6*J7) -> 7937.7542 | K6: =J6+(J6*K7) -> 8275.1088 | L6: =K6+(K6*L7) -> 8626.8009 | M6: =L6+(L6*M7) -> 8993.44 | N6: =M6+(M6*N7) -> 9488.0792 | O6: =N6+(N6*O7) -> 10009.924 | P6: =O6+(O6*P7) -> 10560.469 | ... R6: =Q6+(Q6*R7) -> 11754.066 | S6: =(H6/C6)^(1/4)-1 -> 0.043452786 | T6: =(H6/E6)^(1/3)-1 -> 0.019705646 | U6: =(R6/I6)^(1/9)-1 -> 0.049146125
B7: % YoY growth | D7: =(D6-C6)/C6 -> -0.16849468 | E7: =(E6-D6)/D6 -> 0.34462662 | F7: =(F6-E6)/E6 -> 0.0026727924 | G7: =(G6-F6)/F6 -> 0.078889353 | H7: =(H6-G6)/G6 -> -0.019859501 | I7: 0.04 | J7: 0.04 | K7: 0.0425 | L7: 0.0425 | M7: 0.0425 | N7: 0.055 | O7: 0.055 | P7: 0.055 | Q7: 0.055 | R7: 0.055
B8: Channel Development | C8: 1992.6 | D8: 1925 | E8: 1593.6 | F8: 1843.6 | G8: 1893.8 | H8: 1769.8 | I8: =H8+(H8*I9) -> 1796.347 | J8: =I8+(I8*J9) -> 1823.2922 | K8: =J8+(J8*K9) -> 1850.6416 | L8: =K8+(K8*L9) -> 1878.4012 | M8: =L8+(L8*M9) -> 1906.5772 | N8: =M8+(M8*N9) -> 1935.1759 | O8: =N8+(N8*O9) -> 1964.2035 | P8: =O8+(O8*P9) -> 1993.6666 | ... R8: =Q8+(Q8*R9) -> 2053.9252 | S8: =(H8/C8)^(1/4)-1 -> -0.029208386 | T8: =(H8/E8)^(1/3)-1 -> 0.035575157 | U8: =(R8/I8)^(1/9)-1 -> 0.015
B9: % YoY grwoth | D9: =(D8-C8)/C8 -> -0.033925524 | E9: =(E8-D8)/D8 -> -0.17215584 | F9: =(F8-E8)/E8 -> 0.15687751 | G9: =(G8-F8)/F8 -> 0.027229334 | H9: =(H8-G8)/G8 -> -0.065476819 | I9: 0.015 | J9: 0.015 | K9: 0.015 | L9: 0.015 | M9: 0.015 | N9: 0.015 | O9: 0.015 | P9: 0.015 | Q9: 0.015 | R9: 0.015
B10: TOTAL COMPANY | C10: 26442.3 | D10: 23451.8 | E10: 28963.1 | F10: 32154.5 | G10: 35951 | H10: 36118.2 | I10: =I4+I6+I8 -> 37248.588 | J10: =J4+J6+J8 -> 38415.425 | K10: =K4+K6+K8 -> 39639.76 | L10: =L4+L6+L8 -> 40904.632 | M10: =M4+M6+M8 -> 42211.43 | N10: =N4+N6+N8 -> 43674.011 | O10: =O4+O6+O8 -> 45192.405 | P10: =P4+P6+P8 -> 46768.962 | ... R10: =R4+R6+R8 -> 50106.501 | S10: =(H10/C10)^(1/4)-1 -> 0.081077224 | T10: =(H10/E10)^(1/3)-1 -> 0.076366943 | U10: =(R10/I10)^(1/9)-1 -> 0.033497338
B11: Base Case | D11: =(D10-C10)/C10 -> -0.11309531 | E11: =(E10-D10)/D10 -> 0.23500542 | F11: =(F10-E10)/E10 -> 0.11018848 | G11: =(G10-F10)/F10 -> 0.11807057 | H11: =(H10-G10)/G10 -> 0.0046507747 | I11: =(I10-H10)/H10 -> 0.031296908 | J11: =(J10-I10)/I10 -> 0.031325671 | K11: =(K10-J10)/J10 -> 0.031870929 | ... R11: =(R10-Q10)/Q10 -> 0.035127011
C15: Secondary Approach- Revenue Forecasted by Per Store
B16: Revenue Forecast by Per Store
B17: Year | C17: 2019 | D17: 2020 | E17: 2021 | F17: 2022 | G17: 2023 | H17: 2024 | I17: 2025 | J17: 2026 | K17: 2027 | L17: 2028 | M17: 2029 | N17: 2030 | O17: 2031 | P17: 2032 | Q17: 2033 | R17: 2034
B18: Revenue per Store ($M) | C18: =C10/C94 -> 0.84599117 | D18: =D10/D94 -> 0.71805879 | E18: =E10/E94 -> 0.85606065 | F18: =F10/F94 -> 0.90040884 | G18: =G10/G94 -> 0.94513381 | H18: =H10/H94 -> 0.89848504 | I18: =H18+(I19*H18) -> 0.90567292 | J18: =I18+(J19*I18) -> 0.9129183 | K18: =J18+(K19*J18) -> 0.92022165 | L18: =K18+(L19*K18) -> 0.92942386 | M18: =L18+(M19*L18) -> 0.9387181 | N18: =M18+(N19*M18) -> 0.94810528 | O18: =N18+(O19*N18) -> 0.95758634 | P18: =O18+(P19*O18) -> 0.96955617 | ... R18: =Q18+(R19*Q18) -> 0.99394656
B19: % YoY Growth | D19: =(D18-C18)/C18 -> -0.15122189 | E19: =(E18-D18)/D18 -> 0.19218742 | F19: =(F18-E18)/E18 -> 0.051804959 | G19: =(G18-F18)/F18 -> 0.049671854 | H19: =(H18-G18)/G18 -> -0.049356796 | I19: 0.008 | J19: 0.008 | K19: 0.008 | L19: 0.01 | M19: 0.01 | N19: 0.01 | O19: 0.01 | P19: 0.0125 | Q19: 0.0125 | R19: 0.0125
B20: Total Revenue Forecasted by Per Store | C20: =C94*C18 -> 26442.3 | D20: =D94*D18 -> 23451.8 | E20: =E94*E18 -> 28963.1 | F20: =F94*F18 -> 32154.5 | G20: =G94*G18 -> 35951 | H20: =H94*H18 -> 36118.2 | I20: =I18*I94 -> 37363.714 | J20: =J18*J94 -> 38653.497 | K20: =K18*K94 -> 39989.165 | L20: =L18*L94 -> 41454.485 | M20: =M18*M94 -> 42974.962 | N20: =N18*N94 -> 44552.722 | O20: =O18*O94 -> 46189.976 | P20: =P18*P94 -> 48007.56 | ... R20: =R18*R94 -> 51865.382 | S20: =(R20/I20)^(1/9)-1 -> 0.037111101
B21: % YoY growth | I21: =(I20-H10)/H10 -> 0.034484379 | J21: =(J20-I20)/I20 -> 0.034519665 | K21: =(K20-J20)/J20 -> 0.034554928 | L21: =(L20-K20)/K20 -> 0.036642927 | M21: =(M20-L20)/L20 -> 0.036678211 | N21: =(N20-M20)/M20 -> 0.036713467 | O21: =(O20-N20)/N20 -> 0.036748691 | P21: =(P20-O20)/O20 -> 0.03935018 | Q21: =(Q20-P20)/P20 -> 0.039385423 | R21: =(R20-Q20)/Q20 -> 0.039420628
B22: CAGR 2021-24 | C22: =(H18/E18)^(1/3)-1 -> 0.016253618
B23: CAGR 2025-34 | C23: =(R18/I18)^(1/9)-1 -> 0.010387493
G27: Store Growth Forecasted
B28: Store Type | C28: 2019 | D28: 2020 | E28: 2021 | F28: 2022 | G28: 2023 | H28: 2024 | I28: 2025 | J28: 2026 | K28: 2027 | L28: 2028 | M28: 2029 | N28: 2030 | O28: 2031 | P28: 2032 | Q28: 2033 | R28: 2034
B29: Company-Operated | C29: 15834 | D29: 16637 | E29: 17133 | F29: 18253 | G29: 19592 | H29: 21018 | I29: =H29*(1+I30) -> 21690.576 | J29: =I29*(1+J30) -> 22384.674 | K29: =J29*(1+K30) -> 23100.984 | L29: =K29*(1+L30) -> 23840.216 | M29: =L29*(1+M30) -> 24603.102 | N29: =M29*(1+N30) -> 25390.402 | O29: =N29*(1+O30) -> 26202.895 | P29: =O29*(1+P30) -> 27041.387 | ... R29: =Q29*(1+R30) -> 28799.726
B30: % YoY growth | D30: =(D29-C29)/C29 -> 0.050713654 | E30: =(E29-D29)/D29 -> 0.029813067 | F30: =(F29-E29)/E29 -> 0.065370922 | G30: =(G29-F29)/F29 -> 0.073357804 | H30: =(H29-G29)/G29 -> 0.07278481 | I30: 0.032 | J30: 0.032 | K30: 0.032 | L30: 0.032 | M30: 0.032 | N30: 0.032 | O30: 0.032 | P30: 0.032 | Q30: 0.032 | R30: 0.032
B31: Licensed | C31: 15422 | D31: 16023 | E31: 16700 | F31: 17458 | G31: 18446 | H31: 19181 | I31: =H31*(1+I32) -> 19564.62 | J31: =I31*(1+J32) -> 19955.912 | K31: =J31*(1+K32) -> 20355.031 | L31: =K31*(1+L32) -> 20762.131 | M31: =L31*(1+M32) -> 21177.374 | N31: =M31*(1+N32) -> 21600.921 | O31: =N31*(1+O32) -> 22032.94 | P31: =O31*(1+P32) -> 22473.599 | ... R31: =Q31*(1+R32) -> 23381.532
B32: % YoY growth | D32: =(D31-C31)/C31 -> 0.038970302 | E32: =(E31-D31)/D31 -> 0.042251763 | F32: =(F31-E31)/E31 -> 0.045389222 | G32: =(G31-F31)/F31 -> 0.056592966 | H32: =(H31-G31)/G31 -> 0.039846037 | I32: 0.02 | J32: 0.02 | K32: 0.02 | L32: 0.02 | M32: 0.02 | N32: 0.02 | O32: 0.02 | P32: 0.02 | Q32: 0.02 | R32: 0.02
B33: TOTAL STORES | C33: 31256 | D33: 32660 | E33: 33833 | F33: 35711 | G33: 38038 | H33: 40199 | I33: =I31+I29 -> 41255.196 | J33: =J31+J29 -> 42340.587 | K33: =K31+K29 -> 43456.015 | L33: =L31+L29 -> 44602.347 | M33: =M31+M29 -> 45780.476 | N33: =N31+N29 -> 46991.323 | O33: =O31+O29 -> 48235.834 | P33: =P31+P29 -> 49514.986 | ... R33: =R31+R29 -> 52181.258
B34: % YoY growth | D34: =(D33-C33)/C33 -> 0.044919375 | E34: =(E33-D33)/D33 -> 0.035915493 | F34: =(F33-E33)/E33 -> 0.055507936 | G34: =(G33-F33)/F33 -> 0.065161995 | H34: =(H33-G33)/G33 -> 0.056811609 | I34: =(I33-H33)/H33 -> 0.026274186 | J34: =(J33-I33)/I33 -> 0.026309191 | K34: =(K33-J33)/J33 -> 0.026344175 | ... R34: =(R33-Q33)/Q33 -> 0.026588274
B35: Type of store | C35: CAGR 2019-24 | D35: CAGR 2025-34
B36: Company-Operated CAGR | C36: =(H29/C29)^(1/5)-1 -> 0.05827893 | D36: =(R29/I29)^(1/9)-1 -> 0.032
B37: Licensed CAGR | C37: =(H31/C31)^(1/5)-1 -> 0.04459059 | D37: =(R31/I31)^(1/9)-1 -> 0.02
B38: Total Store CAGR | C38: =(H33/C33)^(1/5)-1 -> 0.051614027 | D38: =(R33/I33)^(1/9)-1 -> 0.026448871
B50: Asset-Based, Bottom-Up CAPEX Forecasting | C50: Historical | D50: Historical | E50: Historical | F50: Historical | G50: Historical | H50: Historical | I50: Forecasted | J50: Forecasted | K50: Forecasted | L50: Forecasted | M50: Forecasted | N50: Forecasted | O50: Forecasted | P50: Forecasted | Q50: Forecasted | R50: Forecasted
B51: Calucation of CAPEX | C51: 2019 | D51: =C51+1 -> 2020 | E51: =D51+1 -> 2021 | F51: =E51+1 -> 2022 | G51: =F51+1 -> 2023 | H51: =G51+1 -> 2024 | I51: 2025F | J51: 2026 | K51: 2027 | L51: 2028 | M51: 2029 | N51: 2030 | O51: 2031 | P51: 2032 | Q51: 2033 | R51: 2034
B52: Revenue | C52: ='Income Statement'!F6 -> 26508.6 | D52: ='Income Statement'!G6 -> 23518 | E52: ='Income Statement'!H6 -> 29060.6 | F52: ='Income Statement'!I6 -> 32250.3 | G52: ='Income Statement'!J6 -> 35975.6 | H52: ='Income Statement'!K6 -> 36176.2 | I52: =I10 -> 37248.588 | J52: =J10 -> 38415.425 | K52: =K10 -> 39639.76 | L52: =L10 -> 40904.632 | M52: =M10 -> 42211.43 | N52: =N10 -> 43674.011 | O52: =O10 -> 45192.405 | P52: =P10 -> 46768.962 | ... R52: =R10 -> 50106.501
B53: CAPEX | C53: =-('Cash Flow '!F33) -> 1806.6 | D53: =-('Cash Flow '!G33) -> 1483.6 | E53: =-('Cash Flow '!H33) -> 1470 | F53: =-('Cash Flow '!I33) -> 1841.3 | G53: =-('Cash Flow '!J33) -> 2333.6 | H53: =-('Cash Flow '!K33) -> 2777.5 | I53: =I59+I60 -> 2907.5093 | J53: =J59+J60 -> 2329.6152 | K53: =K59+K60 -> 2414.3219 | L53: =L59+L60 -> 1878.5481 | M53: =M59+M60 -> 2447.3848 | N53: =N59+N60 -> 2587.4356 | O53: =O59+O60 -> 2679.8745 | P53: =P59+P60 -> 2191.3475 | ... R53: =R59+R60 -> 1801.3006
B54: % of revenue | C54: =C53/C52 -> 0.068151468 | D54: =D53/D52 -> 0.063083596 | E54: =E53/E52 -> 0.050583952 | F54: =F53/F52 -> 0.057094043 | G54: =G53/G52 -> 0.064866187 | H54: =H53/H52 -> 0.076776997 | I54: =I53/I52 -> 0.078056899 | J54: =J53/J52 -> 0.060642702 | ... R54: =R53/R52 -> 0.035949439
B55: Net PP&E | C55: ='Balance Sheet'!F24 -> 6431.7 | D55: ='Balance Sheet'!G24 -> 14375.5 | E55: ='Balance Sheet'!H24 -> 14605.5 | F55: ='Balance Sheet'!I24 -> 14576.1 | G55: ='Balance Sheet'!J24 -> 15799.7 | H55: ='Balance Sheet'!K24 -> 17951.7 | I55: =I52*I56 -> 19183.023 | J55: =J52*J56 -> 19783.944 | K55: =K52*K56 -> 20414.477 | L55: =L52*L56 -> 20452.316 | M55: =M52*M56 -> 21105.715 | N55: =N52*N56 -> 21837.005 | O55: =O52*O56 -> 22596.203 | P55: =P52*P56 -> 22916.792 | ... R55: =R52*R56 -> 22547.925
B56: % of revenue | C56: =C55/C52 -> 0.24262692 | D56: =D55/D52 -> 0.61125521 | E56: =E55/E52 -> 0.5025877 | F56: =F55/F52 -> 0.45196789 | G56: =G55/G52 -> 0.43917822 | H56: =H55/H52 -> 0.49622957 | I56: 0.515 | J56: 0.515 | K56: 0.515 | L56: 0.5 | M56: 0.5 | N56: 0.5 | O56: 0.5 | P56: 0.49 | Q56: 0.47 | R56: 0.45
B57: YoY Growth | D57: =(D55-C55)/D55 -> 0.55259295 | E57: =(E55-D55)/E55 -> 0.015747492 | F57: =(F55-E55)/F55 -> -0.0020170004 | G57: =(G55-F55)/G55 -> 0.077444508 | H57: =(H55-G55)/H55 -> 0.11987723 | I57: =(I55-H55)/I55 -> 0.064188154 | J57: =(J55-I55)/J55 -> 0.030374179 | K57: =(K55-J55)/K55 -> 0.030886546 | ... R57: =(R55-Q55)/R55 -> -0.0090012465
B58: CAPEX/ Net PP&E Ratio | C58: =C53/C55 -> 0.28088997 | D58: =D53/D55 -> 0.10320337 | E58: =E53/E55 -> 0.10064702 | F58: =F53/F55 -> 0.12632323 | G58: =G53/G55 -> 0.14769901 | H58: =H53/H55 -> 0.15472072 | I58: =I53/I55 -> 0.15156679 | J58: =J53/J55 -> 0.11775282 | ... R58: =R53/R55 -> 0.079887642
...

Sheet Balance Sheet
A2: Starbucks Corp (SBUX US) - Standardized
A4: In Millions of USD except Per Share | B4: FY 2015 | C4: FY 2016 | D4: FY 2017 | E4: FY 2018 | F4: FY 2019 | G4: FY 2020 | H4: FY 2021 | I4: FY 2022 | J4: FY 2023 | K4: FY 2024
A5: 12 Months Ending | B5: 09/27/2015 | C5: 42410 | D5: 42745 | E5: 09/30/2018 | F5: 09/29/2019 | G5: 09/27/2020 | H5: 44265 | I5: 44602 | J5: 44936 | K5: 09/29/2024
A6: Total Assets
A7: + Cash, Cash Equivalents & STI | B7: 1611.4 | C7: 2263.2 | D7: 2690.9 | E7: 8937.8 | F7: 2757.1 | G7: 4632.1 | H7: 6617.9 | I7: 3182.9 | J7: 3953 | K7: 3543.2
A8: + Cash & Cash Equivalents | B8: 1530.1 | C8: 2128.8 | D8: 2462.3 | E8: 8756.3 | F8: 2686.6 | G8: 4350.9 | H8: 6455.7 | I8: 2818.4 | J8: 3551.5 | K8: 3286.2
A9: + ST Investments | B9: 81.3 | C9: 134.4 | D9: 228.6 | E9: 181.5 | F9: 70.5 | G9: 281.2 | H9: 162.2 | I9: 364.5 | J9: 401.5 | K9: 257
A10: + Accounts & Notes Receiv | B10: 719 | C10: 768.8 | D10: 870.4 | E10: 693.1 | F10: 879.2 | G10: 883.4 | H10: 940 | I10: 1175.5 | J10: 1184.1 | K10: 1213.8
A11: + Accounts Receivable, Net | B11: 719 | C11: 768.8 | D11: 870.4 | E11: 693.1 | F11: 879.2 | G11: 883.4 | H11: 940 | I11: 1175.5 | J11: 1184.1 | K11: 1213.8
A12: + Notes Receivable, Net | B12: 0 | C12: 0 | D12: 0 | E12: 0 | F12: 0 | G12: 0 | H12: 0 | I12: 0 | J12: 0 | K12: 0
A13: + Inventories | B13: 1306.4 | C13: 1378.5 | D13: 1364 | E13: 1400.5 | F13: 1529.4 | G13: 1551.4 | H13: 1603.9 | I13: 2176.6 | J13: 1806.4 | K13: 1777.3
A14: + Raw Materials | B14: 809.1 | C14: 862 | D14: 842.1 | E14: 869.8 | F14: 933 | G14: 888.2 | H14: 903.8 | I14: 1328.9 | J14: 1028 | K14: 917
A15: + Work In Process | B15: 0 | C15: 0 | D15: 0 | E15: 0 | F15: 0 | G15: 0 | H15: 0 | I15: 0 | J15: 0 | K15: 0
A16: + Finished Goods | B16: 318.3 | C16: 308.6 | D16: 301.1 | E16: 273.1 | F16: 288 | G16: 293.9 | H16: 329.3 | I16: 430.9 | J16: 364.6 | K16: 384.6
A17: + Other Inventory | B17: 179 | C17: 207.9 | D17: 220.8 | E17: 257.6 | F17: 308.4 | G17: 369.3 | H17: 370.8 | I17: 416.8 | J17: 413.8 | K17: 475.7
A18: + Other ST Assets | B18: 334.2 | C18: 350 | D18: 358.1 | E18: 1462.8 | F18: 488.2 | G18: 739.5 | H18: 594.6 | I18: 483.7 | J18: 359.9 | K18: 313.1
A19: + Derivative & Hedging Assets | B19: 50.8 | C19: 27.7 | D19: 24.4 | E19: 10.4 | F19: 12.6 | G19: 15.6 | H19: 147.6 | I19: 75.1 | J19: 41 | K19: 4.8
A20: + Deferred Tax Assets | B20: — | C20: — | D20: — | E20: — | F20: — | G20: — | H20: — | I20: — | J20: — | K20: —
A21: + Taxes Receivable | B21: — | C21: — | D21: — | E21: — | F21: — | G21: 356.9 | H21: 20.7 | I21: 27.7 | J21: — | K21: —
A22: + Misc ST Assets | B22: 283.4 | C22: 322.3 | D22: 333.7 | E22: 1452.4 | F22: 475.6 | G22: 367 | H22: 426.3 | I22: 380.9 | J22: 318.9 | K22: 308.3
A23: Total Current Assets | B23: 3971 | C23: 4760.5 | D23: 5283.4 | E23: 12494.2 | F23: 5653.9 | G23: 7806.4 | H23: 9756.4 | I23: 7018.7 | J23: 7303.4 | K23: 6847.4
A24: + Property, Plant & Equip, Net | B24: 4088.3 | C24: 4533.8 | D24: 4919.5 | E24: 5929.1 | F24: 6431.7 | G24: 14375.5 | H24: 14605.5 | I24: 14576.1 | J24: 15799.7 | K24: 17951.7
A25: + Property, Plant & Equip | B25: 9641.8 | C25: 10573.3 | D25: 11584 | E25: 13197.1 | F25: 14273.5 | G25: 22289.4 | H25: 23064.8 | I25: 23625.4 | J25: 25722.8 | K25: 28727.2
A26: - Accumulated Depreciation | B26: 5553.5 | C26: 6039.5 | D26: 6664.5 | E26: 7268 | F26: 7841.8 | G26: 7913.9 | H26: 8459.3 | I26: 9049.3 | J26: 9923.1 | K26: 10775.5
A27: + LT Investments & Receivables | B27: 312.5 | C27: 1141.7 | D27: 542.3 | E27: 267.7 | F27: 220 | G27: 206.1 | H27: 281.7 | I27: 279.1 | J27: 247.4 | K27: 276
A28: + LT Investments | B28: 312.5 | C28: 1141.7 | D28: 542.3 | E28: 267.7 | F28: 220 | G28: 206.1 | H28: 281.7 | I28: 279.1 | J28: 247.4 | K28: 276
A29: + Other LT Assets | B29: 4044.5 | C29: 3893.5 | D29: 3620.4 | E29: 5465.4 | F29: 6914 | G29: 6986.5 | H29: 6749 | I29: 6104.5 | J29: 6095 | K29: 6264.2
A30: + Total Intangible Assets | B30: 2095.8 | C30: 2235.9 | D30: 1980.6 | E30: 4583.8 | F30: 4272.6 | G30: 4149.3 | H30: 4027.2 | I30: 3439.4 | J30: 3338.8 | K30: 3416.6
A31: + Goodwill | B31: 1575.4 | C31: 1719.6 | D31: 1539.2 | E31: 3541.6 | F31: 3490.8 | G31: 3597.2 | H31: 3677.3 | I31: 3283.5 | J31: 3218.3 | K31: 3315.7
A32: + Other Intangible Assets | B32: 520.4 | C32: 516.3 | D32: 441.4 | E32: 1042.2 | F32: 781.8 | G32: 552.1 | H32: 349.9 | I32: 155.9 | J32: 120.5 | K32: 100.9
A33: + Deferred Tax Assets | B33: 1180.8 | C33: 885.4 | D33: 795.4 | E33: 134.7 | F33: 1765.8 | G33: 1789.9 | H33: 1874.8 | I33: 1799.7 | J33: 1769.8 | K33: 1766.7
A34: + Derivative & Hedging Assets | B34: 54.7 | C34: 6.4 | D34: 13.4 | E34: 24.5 | F34: 26.3 | G34: 87.3 | H34: 84.3 | I34: 156.2 | J34: 153 | K34: 183 | N34: 2019 | O34: =N34+1 -> 2020 | P34: =O34+1 -> 2021 | Q34: =P34+1 -> 2022 | R34: =Q34+1 -> 2023 | S34: =R34+1 -> 2024
A35: + Investments in Affiliates | B35: 352 | C35: 354.5 | D35: 481.6 | E35: 334.7 | F35: 396 | G35: 478.7 | H35: 268.5 | I35: 311.2 | J35: 439.9 | K35: 463.9 | M35: Current Ratio | N35: =F23/F56 -> 0.91654644 | O35: =G23/G56 -> 1.0625578 | P35: =H23/H56 -> 1.1968987 | Q35: =I23/I56 -> 0.76692017 | R35: =J23/J56 -> 0.78150514 | S35: =K23/K56 -> 0.75495039
A36: + Misc LT Assets | B36: 361.2 | C36: 411.3 | D36: 349.4 | E36: 387.7 | F36: 453.3 | G36: 481.3 | H36: 494.2 | I36: 398 | J36: 393.5 | K36: 434
A37: Total Noncurrent Assets | B37: 8445.3 | C37: 9569 | D37: 9082.2 | E37: 11662.2 | F37: 13565.7 | G37: 21568.1 | H37: 21636.2 | I37: 20959.7 | J37: 22142.1 | K37: 24491.9
A38: Total Assets | B38: 12416.3 | C38: 14329.5 | D38: 14365.6 | E38: 24156.4 | F38: 19219.6 | G38: 29374.5 | H38: 31392.6 | I38: 27978.4 | J38: 29445.5 | K38: 31339.3
A40: Liabilities & Shareholders' Equity
A41: + Payables & Accruals | B41: 2420.3 | C41: 2711.7 | D41: 2700.6 | E41: 3684.9 | F41: 4894 | G41: 2945.5 | H41: 4296.5 | I41: 4458.4 | J41: 4514.1 | K41: 4565.2
A42: + Accounts Payable | B42: 684.2 | C42: 730.6 | D42: 782.5 | E42: 1179.3 | F42: 1189.7 | G42: 997.9 | H42: 1211.6 | I42: 1441.4 | J42: 1544.3 | K42: 1595.5
A43: + Accrued Taxes | B43: 259 | C43: 368.4 | D43: 226.6 | E43: 286.6 | F43: 1468.4 | G43: 260.9 | H43: 566 | I43: 333.8 | J43: 212.7 | K43: 211.2
...

Sheet Cash Flow 
A2: Starbucks Corp (SBUX US) - As Reported
A4: In Millions of USD except Per Share | B4: FY 2015 | C4: FY 2016 | D4: FY 2017 | E4: FY 2018 | F4: FY 2019 | G4: FY 2020 | H4: FY 2021 | I4: FY 2022 | J4: FY 2023 | K4: FY 2024
A5: 12 Months Ending | B5: 09/27/2015 | C5: 42410 | D5: 42745 | E5: 09/30/2018 | F5: 09/29/2019 | G5: 09/27/2020 | H5: 44265 | I5: 44602 | J5: 44936 | K5: 09/29/2024
A6: Cash Flow
A7: Cash From Operating Activities
A8: Net Income - CF | B8: 2759.3 | C8: 2818.9 | D8: 2884.9 | E8: 4518 | F8: 3594.6 | G8: 924.7 | H8: 4200.3 | I8: 3283.4 | J8: 4124.7 | K8: 3762.3
A9: Depreciation And Amortization - CF | B9: 933.8 | C9: 1030.1 | D9: 1067.1 | E9: 1305.9 | F9: 1449.3 | G9: 1503.2 | H9: 1524.1 | I9: 1529.4 | J9: 1450.3 | K9: 1592.4
A10: Deferred Income Taxes - CF | B10: 21.2 | C10: 265.7 | D10: 95.1 | E10: 714.9 | F10: -1495.4 | G10: -25.8 | H10: -146.2 | I10: -37.8 | J10: -59.4 | K10: -13.8
A11: Disposal/Sale of Assets | B11: — | C11: — | D11: — | E11: — | F11: — | G11: — | H11: — | I11: — | J11: -91.3 | K11: 0
A12: Stock Based Compensation | B12: 209.8 | C12: 218.1 | D12: 176 | E12: 250.3 | F12: 308 | G12: 248.6 | H12: 319.1 | I12: 271.5 | J12: 302.7 | K12: 308.3
A13: Other Non-Cash Items | B13: 202 | C13: 45.1 | D13: 68.9 | E13: 13.4 | F13: 45.3 | G13: 24.5 | H13: -6 | I13: -67.8 | J13: 26.8 | K13: 31.9
A14: Change in Inventories | B14: -207.9 | C14: -67.5 | D14: 14 | E14: -41.2 | F14: -173 | G14: -10.9 | H14: -49.8 | I14: -641 | J14: 366.4 | K14: 42.8
A15: Change in Accounts Payable | B15: 137.7 | C15: 46.9 | D15: 46.4 | E15: 391.6 | F15: 31.9 | G15: -210.8 | H15: 189.9 | I15: 345.5 | J15: 100.1 | K15: 28
A16: Change in Accounts Receivable | B16: -82.8 | C16: -55.6 | D16: -96.8 | E16: 131 | F16: -197.7 | G16: -2.7 | H16: -43 | I16: -326.1 | J16: -4.1 | K16: 18.4
A17: Change in Accrued Expenses | B17: — | C17: — | D17: — | E17: — | F17: — | G17: — | H17: — | I17: — | J17: — | K17: —
A18: Change in Deferred/Unearned Revenue -ST | B18: 170.3 | C18: 180.4 | D18: 130.8 | E18: 7109.4 | F18: -30.5 | G18: 31 | H18: -6.1 | I18: -75.8 | J18: -110.8 | K18: -72.2
A19: Change in Income Taxes Payable (Receivable) | B19: — | C19: — | D19: -91.9 | E19: 146 | F19: 1237.1 | G19: -1214.6 | H19: 286.1 | I19: -149.6 | J19: 52.5 | K19: -61.9
A20: Change in Other Current Assets | B20: — | C20: — | D20: -20 | E20: -839.5 | F20: 922 | G20: -317.5 | H20: 251.1 | I20: 339.6 | J20: — | K20: —
A21: Equity In Earnings Of Affiliates/JV-CF | B21: -190.2 | C21: -250.2 | D21: -310.2 | E21: -242.8 | F21: -250.6 | G21: -280.7 | H21: -347.3 | I21: -268.7 | J21: -301.8 | K21: -306.4
A22: Impairments | B22: — | C22: — | D22: — | E22: 75.6 | F22: 142.6 | G22: 454.4 | H22: 226.2 | I22: 91.4 | J22: 101.4 | K22: 121.5
A23: Tax Benefit From Exercise of Stock Option-Oper | B23: -132.4 | C23: — | D23: — | E23: — | F23: — | G23: — | H23: — | I23: — | J23: — | K23: —
A24: Total Cash Flows From Operations | B24: 3749.1 | C24: 4697.9 | D24: 4251.8 | E24: 11937.8 | F24: 5047 | G24: 1597.8 | H24: 5989.1 | I24: 4397.3 | J24: 6008.7 | K24: 6095.6
A25: Change In Other Assets And Liabilities | B25: 261.5 | C25: 248.8 | D25: 107.2 | E25: 16.4 | F25: -141.1 | G25: 280.5 | H25: 358.7 | I25: — | J25: -93.7 | K25: 291
A26: Gain/(Loss) On Early Extinguishment of Debt | B26: 61.1 | C26: — | D26: — | E26: — | F26: — | G26: — | H26: — | I26: — | J26: — | K26: —
A27: Impairment Of Goodwill-CF | B27: 0 | C27: 0 | D27: 87.2 | E27: 37.6 | F27: 10.5 | G27: 0 | H27: — | I27: — | J27: — | K27: —
A28: Dividends Received From Joint Ventures | B28: — | C28: 223.3 | D28: 186.6 | E28: 226.8 | F28: 216.8 | G28: 227.7 | H28: 336 | I28: 231.2 | J28: 222.8 | K28: 333.3
A29: Gain/Loss On Disposal Of Affiliates | B29: — | C29: 0 | D29: 0 | E29: -1376.4 | F29: — | G29: — | H29: — | I29: — | J29: — | K29: —
A30: Gain/Loss On Disposal Of Subsidiaries | B30: -394.3 | C30: -6.1 | D30: -93.5 | E30: -499.2 | F30: -622.8 | G30: 0 | H30: -864.5 | I30: 0 | J30: 0 | K30: —
A31: Cash From Investing Activities
A32: Disposal of Fixed Assets | B32: — | C32: — | D32: — | E32: — | F32: — | G32: — | H32: — | I32: — | J32: 110 | K32: 0
A33: Capital Expenditures | B33: -1303.7 | C33: -1440.3 | D33: -1519.4 | E33: -1976.4 | F33: -1806.6 | G33: -1483.6 | H33: -1470 | I33: -1841.3 | J33: -2333.6 | K33: -2777.5
A34: Proceeds From Investments | B34: 619.4 | C34: 680.7 | D34: 1054.5 | E34: 459 | F34: 298.3 | G34: 186.7 | H34: 143.2 | I34: 72.6 | J34: 2.5 | K34: 10.3
A35: Purchases of Investments | B35: -567.4 | C35: -1585.7 | D35: -674.4 | E35: -191.9 | F35: -190.4 | G35: -443.9 | H35: -432 | I35: -377.9 | J35: -610.5 | K35: -627.5
A36: Acquisition of Business | B36: -284.3 | C36: 0 | D36: 0 | E36: — | F36: — | G36: — | H36: — | I36: — | J36: — | K36: —
A37: Other Investing Activities | B37: 15.7 | C37: 24.9 | D37: 54.3 | E37: 5.6 | F37: -56.2 | G37: -44.4 | H37: -81.2 | I37: -126.3 | J37: -56.1 | K37: -72.7
A38: Divestiture of Business | B38: — | C38: — | D38: — | E38: — | F38: — | G38: 0 | H38: 1175 | I38: 59.3 | J38: 0 | K38: 0
A39: Proceeds From Sale Of Assocs/Joint Ventures | B39: — | C39: 69.6 | D39: 85.4 | E39: 608.2 | F39: 684.3 | G39: — | H39: — | I39: — | J39: — | K39: —
A40: Purchase Of Associates/Joint Ventures | B40: — | C40: — | D40: — | E40: -1311.3 | F40: — | G40: — | H40: — | I40: — | J40: — | K40: —
A41: Total Cash Flows From Investing | B41: -1520.3 | C41: -2222.9 | D41: -850 | E41: -2361.5 | F41: -1010.8 | G41: -1711.5 | H41: -319.5 | I41: -2146.3 | J41: -2270.8 | K41: -2699.2
A42: Cash from Financing Activities
...

Sheet Income Statement
A2: Starbucks Corp (SBUX US) - BBG Adjusted
A4: In Millions of USD except Per Share | B4: FY 2015 | C4: FY 2016 | D4: FY 2017 | E4: FY 2018 | F4: FY 2019 | G4: FY 2020 | H4: FY 2021 | I4: FY 2022 | J4: FY 2023 | K4: FY 2024
A5: 12 Months Ending | B5: 09/27/2015 | C5: 42410 | D5: 42745 | E5: 09/30/2018 | F5: 09/29/2019 | G5: 09/27/2020 | H5: 44265 | I5: 44602 | J5: 44936 | K5: 09/29/2024
A6: Revenue | B6: 19162.7 | C6: 21315.9 | D6: 22386.8 | E6: 24719.5 | F6: 26508.6 | G6: 23518 | H6: 29060.6 | I6: 32250.3 | J6: 35975.6 | K6: 36176.2
A7: Growth (YoY) | B7: 16.5 | C7: 11.2 | D7: 5 | E7: 10.4 | F7: 7.2 | G7: -11.3 | H7: 23.6 | I7: 11 | J7: 11.6 | K7: 0.6
A8: + Sales & Services Revenue | B8: 17300.8 | C8: 19161.7 | D8: 20005.7 | E8: 22067.3 | F8: 23633.6 | G8: 21190.9 | H8: 26377 | I8: 28594.8 | J8: 31462.9 | K8: 31671.1
A9: Growth (YoY) | B9: 16.4 | C9: 10.8 | D9: 4.4 | E9: 10.3 | F9: 7.1 | G9: -10.3 | H9: 24.5 | I9: 8.4 | J9: 10 | K9: 0.7
A10: + Other Revenue | B10: 1861.9 | C10: 2154.2 | D10: 2381.1 | E10: 2652.2 | F10: 2875 | G10: 2327.1 | H10: 2683.6 | I10: 3655.5 | J10: 4512.7 | K10: 4505.1
A11: Growth (YoY) | B11: 17.2 | C11: 15.7 | D11: 10.5 | E11: 11.4 | F11: 8.4 | G11: -19.1 | H11: 15.3 | I11: 36.2 | J11: 23.4 | K11: -0.2
A12: - Cost of Revenue | B12: 13198.6 | C12: 14573.3 | D12: 15552.2 | E12: 17402.9 | F12: 19020.5 | G12: 18458.9 | H12: 20652 | I12: 23879.2 | J12: 26129.4 | K12: 26467.1
A13: Growth (YoY) | B13: 14.8 | C13: 10.4 | D13: 6.7 | E13: 11.9 | F13: 9.3 | G13: -3 | H13: 11.9 | I13: 15.6 | J13: 9.4 | K13: 1.3
A14: + Cost of Goods & Services | B14: 13198.6 | C14: 14573.3 | D14: 15552.2 | E14: 17402.9 | F14: 19020.5 | G14: 18458.9 | H14: 20652 | I14: 23879.2 | J14: 26129.4 | K14: 26467.1 | L14: =(K14/B14)^(1/9)-1 -> 0.080377144
A15: Growth (YoY) | B15: 14.8 | C15: 10.4 | D15: 6.7 | E15: 11.9 | F15: 9.3 | G15: -3 | H15: 11.9 | I15: 15.6 | J15: 9.4 | K15: 1.3 | L15: =AVERAGE(B15:K15) -> 8.83
A16: Gross Profit | B16: 5964.1 | C16: 6742.6 | D16: 6834.6 | E16: 7316.6 | F16: 7488.1 | G16: 5059.1 | H16: 8408.6 | I16: 8371.1 | J16: 9846.2 | K16: 9709.1
A17: Growth (YoY) | B17: 20.5 | C17: 13.1 | D17: 1.4 | E17: 7.1 | F17: 2.3 | G17: -32.4 | H17: 66.2 | I17: -0.4 | J17: 17.6 | K17: -1.4
A18: + Other Operating Income | B18: 0 | C18: 318.2 | D18: 391.4 | E18: 301.2 | F18: 298 | G18: 322.5 | H18: 385.3 | I18: 234.1 | J18: 298.4 | K18: 301.2
A19: Growth (YoY) | B19: — | C19: — | D19: 23 | E19: -23 | F19: -1.1 | G19: 8.2 | H19: 19.5 | I19: -39.2 | J19: 27.5 | K19: 0.9
A20: - Operating Expenses | B20: 2308.5 | C20: 2888.9 | D20: 2874.8 | E20: 3122.8 | F20: 3215.6 | G20: 3248.4 | H20: 3576 | I20: 3750.2 | J20: 4343.2 | K20: 4480
A21: Growth (YoY) | B21: 22.1 | C21: 25.1 | D21: -0.5 | E21: 8.6 | F21: 3 | G21: 1 | H21: 10.1 | I21: 4.9 | J21: 15.8 | K21: 3.1
A22: + Selling, General & Admin | B22: 1424.6 | C22: 1657.5 | D22: 1691 | E22: 1968.5 | F22: 2029 | G22: 1922.2 | H22: 2215.5 | I22: 2448.7 | J22: 2949.1 | K22: 2523.3
A23: Growth (YoY) | B23: 19.7 | C23: 16.3 | D23: 2 | E23: 16.4 | F23: 3.1 | G23: -5.3 | H23: 15.3 | I23: 10.5 | J23: 20.4 | K23: -14.4
A24: + Selling & Marketing | B24: 227.9 | C24: 248.6 | D24: 282.6 | E24: 260.3 | F24: 245.7 | G24: 258.8 | H24: 305.1 | I24: 416.7 | J24: 507.8 | K24: —
A25: Growth (YoY) | B25: 14.6 | C25: 9.1 | D25: 13.7 | E25: -7.9 | F25: -5.6 | G25: 5.3 | H25: 17.9 | I25: 36.6 | J25: 21.9 | K25: —
A26: + General & Administrative | B26: 1196.7 | C26: 1408.9 | D26: 1408.4 | E26: 1708.2 | F26: 1783.3 | G26: 1663.4 | H26: 1910.4 | I26: 2032 | J26: 2441.3 | K26: 2523.3
A27: Growth (YoY) | B27: 20.7 | C27: 17.7 | D27: 0 | E27: 21.3 | F27: 4.4 | G27: -6.7 | H27: 14.8 | I27: 6.4 | J27: 20.1 | K27: 3.4
A28: + Research & Development | B28: 0 | C28: 0 | D28: 0 | E28: 0 | F28: — | G28: 0 | H28: 0 | I28: 0 | J28: 0 | K28: 0
A29: + Depreciation & Amortization | B29: 893.9 | C29: 980.8 | D29: 1011.4 | E29: 1247 | F29: 1377.3 | G29: 1431.3 | H29: 1441.7 | I29: 1447.9 | J29: 1362.6 | K29: 1512.6
A30: Growth (YoY) | B30: 26 | C30: 9.7 | D30: 3.1 | E30: 23.3 | F30: 10.4 | G30: 3.9 | H30: 0.7 | I30: 0.4 | J30: -5.9 | K30: 11
A31: + Other Operating Expense | B31: -10 | C31: 250.6 | D31: 172.4 | E31: -92.7 | F31: -190.7 | G31: -105.1 | H31: -81.2 | I31: -146.4 | J31: 31.5 | K31: 444.1
A32: Growth (YoY) | B32: -1 | C32: — | D32: -31.2 | E32: — | F32: -105.7 | G32: 44.9 | H32: 22.7 | I32: -80.3 | J32: — | K32: 1309.8
A33: Operating Income (Loss) | B33: 3655.6 | C33: 4171.9 | D33: 4351.2 | E33: 4495 | F33: 4570.5 | G33: 2133.2 | H33: 5217.9 | I33: 4855 | J33: 5801.4 | K33: 5530.3
A34: Growth (YoY) | B34: 19.4 | C34: 14.1 | D34: 4.3 | E34: 3.3 | F34: 1.7 | G34: -53.3 | H34: 144.6 | I34: -7 | J34: 19.5 | K34: -4.7
A35: - Non-Operating (Income) Loss | B35: 27.5 | C35: -21.3 | D35: -89.3 | E35: -21.1 | F35: 234.5 | G35: 397.3 | H35: 379.7 | I35: 385.9 | J35: 468.9 | K35: 439.2
A36: Growth (YoY) | B36: — | C36: — | D36: -319.2 | E36: 76.4 | F36: — | G36: 69.4 | H36: -4.4 | I36: 1.6 | J36: 21.5 | K36: -6.3
A37: + Interest Expense, Net | B37: — | C37: — | D37: — | E37: — | F37: — | G37: — | H37: — | I37: 482.9 | J37: 550.1 | K37: 562
A38: Growth (YoY) | B38: — | C38: — | D38: — | E38: — | F38: — | G38: — | H38: — | I38: — | J38: 13.9 | K38: 2.2
A39: + Interest Expense | B39: 70.5 | C39: 81.3 | D39: 92.5 | E39: 170.3 | F39: 331 | G39: 437 | H39: 469.8 | I39: 482.9 | J39: 550.1 | K39: 562
A40: Growth (YoY) | B40: 10 | C40: 15.3 | D40: 13.8 | E40: 84.1 | F40: 94.4 | G40: 32 | H40: 7.5 | I40: 2.8 | J40: 13.9 | K40: 2.2
A41: - Interest Income | B41: — | C41: — | D41: — | E41: — | F41: — | G41: — | H41: — | I41: 0 | J41: 0 | K41: 0
A42: + Foreign Exch (Gain) Loss | B42: 0 | C42: 0 | D42: 0 | E42: 0 | F42: 0 | G42: 0 | H42: 0 | I42: 0 | J42: 0 | K42: 0
...
